# try...except结构

> 最基础的异常处理结构，在try里面写被监控的语句，若产生异常就跳过剩余try中的代码，去寻找except有没有匹配的异常，成功找到了就执行该语句块内部的内容

```python
try:
    a += 1
    print('hello')
except NameError:
    print('变量不存在')  # 变量不存在
```

---

## 带多个except

> 可以用多个except判断多个条件，类似else if的用法

```python
try:
    # a = 5
    a += 1
    print('hello')
except ZeroDivisionError:
    print('除数不能为0')
except NameError:
    print('变量不存在') 
else:
    print('正常退出')

'''
变量不存在
'''
```

---

# try...except...else结构

> 如果try范围内没有捕获异常则会执行else语句

```python
try:
    a = 5
    a += 1
    print('hello')
except NameError:
    print('变量不存在')  
else:
    print('正常退出')

'''
hello
正常退出
'''
```

**注意：如果出现了错误，但是except没有捕获到是会报错退出的，并不会继续下去执行else**

```python
try:
    # a = 5
    a += 1
    print('hello')
except ZeroDivisionError:
    print('变量不存在')  
else:
    print('正常退出')

'''
NameError: name 'a' is not defined
'''
```

---

# try...except...finally结构

> finally内的内容无论是否发生异常都会执行，一般用来执行关闭打开的文件子类的操作

## Code1

> 捕获到异常退出

```python
try:
    # a = 5
    a += 1
    print('hello')
except ZeroDivisionError:
    print('除数不能为0')
except NameError:
    print('变量不存在') 
else:
    print('正常退出')
finally:
    print('程序结束')

'''
变量不存在
程序结束
'''
```

---

## Code2

> 未发生异常，正常执行完退出

```python
try:
    a = 5
    a += 1
    print('hello')
except ZeroDivisionError:
    print('除数不能为0')
except NameError:
    print('变量不存在') 
else:
    print('正常退出')
finally:
    print('程序结束')

'''
hello
正常退出
程序结束
'''
```

---

## Code3

> 发生异常，但是捕获失败，也会执行后报错

```python
try:
    # a = 5
    a += 1
    print('hello')
except ZeroDivisionError:
    print('除数不能为0')
# except NameError:
#     print('变量不存在') 
else:
    print('正常退出')
finally:
    print('程序结束')

'''
程序结束
NameError: name 'a' is not defined
'''
```

---

# 多个捕获写在一起

## except一行多个捕获

### Code1

> 捕获到NameError

```python
try:
    # a = 5
    a += 1
    print('hello')
except (ZeroDivisionError, NameError):
    print('error')


'''
error
'''
```

---

### Code2

> 捕获到ZeroDivisionError

```python
try:
    # a = 5
    a = 5 / 0
    print('hello')
except (ZeroDivisionError, NameError):
    print('error')


'''
error
'''
```

---

## 直接捕获异常父类

> 捕获异常的过程是这样的：程序在运行的过程中发生异常就会抛出异常，然后捕获该异常，去except中一个个判断属于哪个类，于是肯定也能被父类捕获

```python
try:
    # a = 5
    a = 5 / 0
    print('hello')
except Exception:
    print('error')


'''
error
'''
```

---

# 捕获默认异常

> 在我们懒得写异常类的情况下，可以不写，而只写一个except，这就是出错时的默认捕获

```python
try:
    # a = 5
    a = 5 / 0
    print('hello')
except:
    print('error')


'''
error
'''
```

**注意：这个默认捕获只能写在其他的捕获后面**

```python
try:
    # a = 5
    a = 5 / 0
    print('hello')
except:
    print('error')
except NameError:
    print('name')


'''
SyntaxError: default 'except:' must be last
'''
```

# 捕获异常的描述信息

> 我们可以在except捕获时，直接接收这个抛出的异常对象，然后打印出异常原因

```python
try:
    # a = 5
    a = 5 / 0
    print('hello')
except Exception as e:
    print(f'error:{e}')


'''
error:division by zero
'''
```

---

# 主动抛出异常

## 抛出异常类

语法：`raise 异常类名`

```python
raise NameError

'''
NameError
'''
```

## 抛出异常对象

语法：`raise 异常对象`

```python
e = NameError()
raise e

'''
NameError
'''
```

## 传递异常

语法：`raise`

> 默认会抛出上一个异常

```python
try:
    a = 3 / 0
except:
    print('error')
    raise

'''
error
ZeroDivisionError: division by zero
'''
```

## 指定异常的描述

```python
e = NameError('名字错了呢')
raise e

'''
NameError: 名字错了呢
'''
```

## 捕获自己抛出的异常

> 自己抛出的异常和系统抛出的没什么两样，同样会被捕获处理

```python
try:
    e = NameError('名字错了呢')
    raise e
except NameError as e:
    print('name')        # name     
    print(e)             # 名字错了呢  
```

---

# 自定义异常类

> 只要是继承自异常类的类都可以被主动抛出

```python
class MyExcept(Exception):
    def __init__(self, name = '', score = 0) -> None:
        self.name = name
        self.score = score

try:
    name = 'wang'
    score = 150
    if score:
        raise MyExcept(name, score)
except MyExcept as e:
    print(e)                          # ('wang', 150)            
    print(e.name, e.score)            # wang 150       
```

---

# 断言

## 语法

`assert expression[, reason]`

> 当expression为真则什么都不做，如果为假则会发生断言报错，如果填写了理由则会打印理由

## Code1

> 出错打印理由

```python
a = 5
b = 6
assert a == b, 'a必须和b相等'

'''
AssertionError: a必须和b相等
'''
```

---

## Code2

> 出错无理由

```python
a = 5
b = 6
assert a == b#, 'a必须和b相等'

'''
AssertionError
'''
```



