# try-catch-finally结构

try内的语句块用来监视可能产生异常的语句，后可接0到多个catch语句。

**注意：若没有catch语句，则一定要有finally语句**，其他情况下，finally可以选择舍弃

## 执行过程

若没有任何错误，则执行完try语句，并跳到finally语句执行，略过中间所有的catch

若出现了异常，则不再进行try剩余的语句，而是逐一匹配catch语句，最后再执行finally语句

若try或catch语句中有return语句，则在触发return时会先跳转到finally语句执行完再return

---

# throw手动抛出异常

必须要抛出异常对象才行

**注意：尽量在try中用，不然程序直接报错了就不好控制了**

**还有一个要注意的点：抛出异常最好要在判断中，如果凭空抛出的话，聪明的编译器直接就会认为你压根不想执行下面的操作，根本就是在玩弄编译器**

```java
import java.util.InputMismatchException;
import java.util.Scanner;

class Main {
    public static void main(String[] args) {
        try {
            int a = 1;
            if (a > 0)
                throw new ArithmeticException();
            System.out.println("hello world");
        }
        catch (ArithmeticException e) {
            System.out.println("ArithmeticException");
        }
        finally {
            System.out.println("finally");
        }
    }
}
```

> 输出：
>
> ArithmeticException
> finally
>
> 抛出异常后，直接去处理异常了，hello world没有输出

## 妙用

用自己定义的异常类继承了Exception就可以被抛出，这样就可以实现自己造异常了

```java
import java.util.InputMismatchException;
import java.util.Scanner;

class MyException extends Exception {
    String msg;
    public MyException(String msg) {
        super(msg);
        this.msg = msg;
    }

    public String toString() {
        return msg;
    }
}

class Main {
    public static void main(String[] args) {
        try {
            int a = 1;
            if (a > 0)
                throw new MyException("a > 0");
            System.out.println("hello world");
        }
        catch (MyException e) {
            System.out.println(e.toString());
        }
        finally {
            System.out.println("finally");
        }
    }
}
```

> 输出：
>
> a > 0
> finally
>
> 同样也没有hello world